<?xml version="1.0" ?>
<robot name="simple_four_wheels" xmlns:xacro="http://www.ros.org/wiki/xacro">

<xacro:include filename="$(find simple_four_wheels_description)/urdf/materials.xacro" />
<xacro:include filename="$(find simple_four_wheels_description)/urdf/simple_four_wheels.trans" />
<xacro:include filename="$(find simple_four_wheels_description)/urdf/simple_four_wheels.gazebo" />
<link name="base_link">
  <inertial>
    <origin xyz="0.00014946656090056147 0.0 0.0025099644374021166" rpy="0 0 0"/>
    <mass value="0.4726809767637952"/>
    <inertia ixx="0.000396" iyy="0.00057" izz="0.000963" ixy="0.0" iyz="0.0" ixz="-0.0"/>
  </inertial>
  <visual>
    <origin xyz="0 0 0" rpy="0 0 0"/>
    <geometry>
      <mesh filename="file://$(find simple_four_wheels_description)/meshes/base_link.stl" scale="0.001 0.001 0.001"/>
    </geometry>
    <material name="silver"/>
  </visual>
  <collision>
    <origin xyz="0 0 0" rpy="0 0 0"/>
    <geometry>
      <mesh filename="file://$(find simple_four_wheels_description)/meshes/base_link.stl" scale="0.001 0.001 0.001"/>
    </geometry>
  </collision>
</link>

<link name="left_wheel_2_1">
  <inertial>
    <origin xyz="-6.705522526129215e-10 0.0024999999999999883 3.7252904754037086e-11" rpy="0 0 0"/>
    <mass value="0.012330751165339937"/>
    <inertia ixx="0.0" iyy="1e-06" izz="0.0" ixy="0.0" iyz="-0.0" ixz="0.0"/>
  </inertial>
  <visual>
    <origin xyz="0.045 -0.0505 -0.0025" rpy="0 0 0"/>
    <geometry>
      <mesh filename="file://$(find simple_four_wheels_description)/meshes/left_wheel_2_1.stl" scale="0.001 0.001 0.001"/>
    </geometry>
    <material name="silver"/>
  </visual>
  <collision>
    <origin xyz="0.045 -0.0505 -0.0025" rpy="0 0 0"/>
    <geometry>
      <mesh filename="file://$(find simple_four_wheels_description)/meshes/left_wheel_2_1.stl" scale="0.001 0.001 0.001"/>
    </geometry>
  </collision>
</link>

<link name="right_wheel_1_1">
  <inertial>
    <origin xyz="6.705522526129215e-10 -0.0024999999999999883 3.7252904754037086e-11" rpy="0 0 0"/>
    <mass value="0.012330751165339937"/>
    <inertia ixx="0.0" iyy="1e-06" izz="0.0" ixy="0.0" iyz="-0.0" ixz="0.0"/>
  </inertial>
  <visual>
    <origin xyz="-0.045 0.0505 -0.0025" rpy="0 0 0"/>
    <geometry>
      <mesh filename="file://$(find simple_four_wheels_description)/meshes/right_wheel_1_1.stl" scale="0.001 0.001 0.001"/>
    </geometry>
    <material name="silver"/>
  </visual>
  <collision>
    <origin xyz="-0.045 0.0505 -0.0025" rpy="0 0 0"/>
    <geometry>
      <mesh filename="file://$(find simple_four_wheels_description)/meshes/right_wheel_1_1.stl" scale="0.001 0.001 0.001"/>
    </geometry>
  </collision>
</link>

<link name="right_wheel_2_1">
  <inertial>
    <origin xyz="-6.705522526129215e-10 -0.0024999999999999883 3.7252904754037086e-11" rpy="0 0 0"/>
    <mass value="0.012330751165339937"/>
    <inertia ixx="0.0" iyy="1e-06" izz="0.0" ixy="-0.0" iyz="-0.0" ixz="0.0"/>
  </inertial>
  <visual>
    <origin xyz="0.045 0.0505 -0.0025" rpy="0 0 0"/>
    <geometry>
      <mesh filename="file://$(find simple_four_wheels_description)/meshes/right_wheel_2_1.stl" scale="0.001 0.001 0.001"/>
    </geometry>
    <material name="silver"/>
  </visual>
  <collision>
    <origin xyz="0.045 0.0505 -0.0025" rpy="0 0 0"/>
    <geometry>
      <mesh filename="file://$(find simple_four_wheels_description)/meshes/right_wheel_2_1.stl" scale="0.001 0.001 0.001"/>
    </geometry>
  </collision>
</link>

<link name="left_wheel_1_1">
  <inertial>
    <origin xyz="6.705522456740276e-10 0.0024999999999999883 3.725291169293099e-11" rpy="0 0 0"/>
    <mass value="0.012330751165339937"/>
    <inertia ixx="0.0" iyy="1e-06" izz="0.0" ixy="-0.0" iyz="-0.0" ixz="-0.0"/>
  </inertial>
  <visual>
    <origin xyz="-0.045 -0.0505 -0.0025" rpy="0 0 0"/>
    <geometry>
      <mesh filename="file://$(find simple_four_wheels_description)/meshes/left_wheel_1_1.stl" scale="0.001 0.001 0.001"/>
    </geometry>
    <material name="silver"/>
  </visual>
  <collision>
    <origin xyz="-0.045 -0.0505 -0.0025" rpy="0 0 0"/>
    <geometry>
      <mesh filename="file://$(find simple_four_wheels_description)/meshes/left_wheel_1_1.stl" scale="0.001 0.001 0.001"/>
    </geometry>
  </collision>
</link>

<link name="right_cam_1">
  <inertial>
    <origin xyz="2.675393073642285e-05 -1.8066378496689461e-07 0.00752491787548288" rpy="0 0 0"/>
    <mass value="0.01775564430500639"/>
    <inertia ixx="1e-06" iyy="0.0" izz="0.0" ixy="0.0" iyz="0.0" ixz="-0.0"/>
  </inertial>
  <visual>
    <origin xyz="-0.045 0.035 -0.006" rpy="0 0 0"/>
    <geometry>
      <mesh filename="file://$(find simple_four_wheels_description)/meshes/right_cam_1.stl" scale="0.001 0.001 0.001"/>
    </geometry>
    <material name="silver"/>
  </visual>
  <collision>
    <origin xyz="-0.045 0.035 -0.006" rpy="0 0 0"/>
    <geometry>
      <mesh filename="file://$(find simple_four_wheels_description)/meshes/right_cam_1.stl" scale="0.001 0.001 0.001"/>
    </geometry>
  </collision>
</link>

<link name="left_cam_1">
  <inertial>
    <origin xyz="2.6753930736402032e-05 1.8066378496689461e-07 0.007524917875482751" rpy="0 0 0"/>
    <mass value="0.01775564430500639"/>
    <inertia ixx="1e-06" iyy="0.0" izz="0.0" ixy="-0.0" iyz="-0.0" ixz="-0.0"/>
  </inertial>
  <visual>
    <origin xyz="-0.045 -0.035 -0.006" rpy="0 0 0"/>
    <geometry>
      <mesh filename="file://$(find simple_four_wheels_description)/meshes/left_cam_1.stl" scale="0.001 0.001 0.001"/>
    </geometry>
    <material name="silver"/>
  </visual>
  <collision>
    <origin xyz="-0.045 -0.035 -0.006" rpy="0 0 0"/>
    <geometry>
      <mesh filename="file://$(find simple_four_wheels_description)/meshes/left_cam_1.stl" scale="0.001 0.001 0.001"/>
    </geometry>
  </collision>
</link>
<link name="left_cam_1_optical"></link>
<link name="right_cam_1_optical"></link>

<joint name="l_wheel_joint_2" type="continuous">
  <origin xyz="-0.045 0.0505 0.0025" rpy="0 0 0"/>
  <parent link="base_link"/>
  <child link="left_wheel_2_1"/>
  <axis xyz="0.0 1.0 0.0"/>
</joint>

<joint name="r_wheel_joint_1" type="continuous">
  <origin xyz="0.045 -0.0505 0.0025" rpy="0 0 0"/>
  <parent link="base_link"/>
  <child link="right_wheel_1_1"/>
  <axis xyz="0.0 1.0 0.0"/>
</joint>

<joint name="r_wheel_joint_2" type="continuous">
  <origin xyz="-0.045 -0.0505 0.0025" rpy="0 0 0"/>
  <parent link="base_link"/>
  <child link="right_wheel_2_1"/>
  <axis xyz="0.0 -1.0 0.0"/>
</joint>

<joint name="l_wheel_joint_1" type="continuous">
  <origin xyz="0.045 0.0505 0.0025" rpy="0 0 0"/>
  <parent link="base_link"/>
  <child link="left_wheel_1_1"/>
  <axis xyz="0.0 1.0 0.0"/>
</joint>

<joint name="r_cam_joint" type="fixed">
  <origin xyz="0.045 -0.035 0.006" rpy="0 0 0"/>
  <parent link="base_link"/>
  <child link="right_cam_1"/>
</joint>

<joint name="r_cam_optical_joint" type="fixed">
  <origin xyz="0.045 -0.035 0.006" rpy="0 0 0"/>
  <parent link="right_cam_1"/>
  <child link="right_cam_1_optical"/>
</joint>

<joint name="l_cam_joint" type="fixed">
  <origin xyz="0.045 0.035 0.006" rpy="0 0 0"/>
  <parent link="base_link"/>
  <child link="left_cam_1"/>
</joint>

<joint name="l_cam_optical_joint" type="fixed">
  <origin xyz="0.045 0.035 0.006" rpy="0 0 0"/>
  <parent link="left_cam_1"/>
  <child link="left_cam_1_optical"/>
</joint>

</robot>
