<?xml version="1.0" ?>
<robot name="assembly_refined" xmlns:xacro="http://www.ros.org/wiki/xacro">

<xacro:include filename="$(find assembly_refined_description)/urdf/materials.xacro" />
<xacro:include filename="$(find assembly_refined_description)/urdf/assembly_refined.trans" />
<xacro:include filename="$(find assembly_refined_description)/urdf/assembly_refined.gazebo" />
<link name="base_link">
  <inertial>
    <origin xyz="3.7934004633975368e-06 -0.002551677682088614 0.018819185995272276" rpy="0 0 0"/>
    <mass value="0.150"/>
    <inertia ixx="0.00025" iyy="0.000119" izz="0.000352" ixy="0.0" iyz="3.7e-05" ixz="-0.0"/>
  </inertial>
  <visual>
    <origin xyz="0 0 0" rpy="0 0 0"/>
    <geometry>
      <mesh filename="file://$(find assembly_refined_description)/meshes/base_link.stl" scale="0.001 0.001 0.001"/>
    </geometry>
    <material name="silver"/>
  </visual>
  <collision>
    <origin xyz="0 0 0" rpy="0 0 0"/>
    <geometry>
      <mesh filename="file://$(find assembly_refined_description)/meshes/base_link.stl" scale="0.001 0.001 0.001"/>
    </geometry>
  </collision>
</link>

<link name="motor_mount_v3_1">
  <inertial>
    <origin xyz="0.0014026196964651155 -0.008004803677416017 -0.00777855916822159" rpy="0 0 0"/>
    <mass value="0.02"/>
    <inertia ixx="1e-06" iyy="1e-06" izz="1e-06" ixy="0.0" iyz="-0.0" ixz="0.0"/>
  </inertial>
  <visual>
    <origin xyz="-0.0479 0.066989 -0.035" rpy="0 0 0"/>
    <geometry>
      <mesh filename="file://$(find assembly_refined_description)/meshes/motor_mount_v3_1.stl" scale="0.001 0.001 0.001"/>
    </geometry>
    <material name="silver"/>
  </visual>
  <collision>
    <origin xyz="-0.0479 0.066989 -0.035" rpy="0 0 0"/>
    <geometry>
      <mesh filename="file://$(find assembly_refined_description)/meshes/motor_mount_v3_1.stl" scale="0.001 0.001 0.001"/>
    </geometry>
  </collision>
</link>

<link name="motor_mount_v3__1__1">
  <inertial>
    <origin xyz="-0.001402619696465067 0.008004912738705322 -0.007778559168221844" rpy="0 0 0"/>
    <mass value="0.02"/>
    <inertia ixx="1e-06" iyy="1e-06" izz="1e-06" ixy="0.0" iyz="0.0" ixz="-0.0"/>
  </inertial>
  <visual>
    <origin xyz="0.0475 0.082989 -0.035" rpy="0 0 0"/>
    <geometry>
      <mesh filename="file://$(find assembly_refined_description)/meshes/motor_mount_v3__1__1.stl" scale="0.001 0.001 0.001"/>
    </geometry>
    <material name="silver"/>
  </visual>
  <collision>
    <origin xyz="0.0475 0.082989 -0.035" rpy="0 0 0"/>
    <geometry>
      <mesh filename="file://$(find assembly_refined_description)/meshes/motor_mount_v3__1__1.stl" scale="0.001 0.001 0.001"/>
    </geometry>
  </collision>
</link>

<link name="motor_dummy_v2_1">
  <inertial>
    <origin xyz="0.025869935421598177 2.3361652069786576e-07 3.6891150121017013e-07" rpy="0 0 0"/>
    <mass value="0.4"/>
    <inertia ixx="1.6e-05" iyy="5.5e-05" izz="5.5e-05" ixy="-0.0" iyz="0.0" ixz="0.0"/>
  </inertial>
  <visual>
    <origin xyz="0.057 0.07581 -0.015243" rpy="0 0 0"/>
    <geometry>
      <mesh filename="file://$(find assembly_refined_description)/meshes/motor_dummy_v2_1.stl" scale="0.001 0.001 0.001"/>
    </geometry>
    <material name="silver"/>
  </visual>
  <collision>
    <origin xyz="0.057 0.07581 -0.015243" rpy="0 0 0"/>
    <geometry>
      <mesh filename="file://$(find assembly_refined_description)/meshes/motor_dummy_v2_1.stl" scale="0.001 0.001 0.001"/>
    </geometry>
  </collision>
</link>

<link name="motor_dummy_v2__1__1">
  <inertial>
    <origin xyz="-0.02586993542159822 -1.2455523139276448e-07 3.6891150185548727e-07" rpy="0 0 0"/>
    <mass value="0.4"/>
    <inertia ixx="1.6e-05" iyy="5.5e-05" izz="5.5e-05" ixy="-0.0" iyz="0.0" ixz="-0.0"/>
  </inertial>
  <visual>
    <origin xyz="-0.0574 0.074168 -0.015243" rpy="0 0 0"/>
    <geometry>
      <mesh filename="file://$(find assembly_refined_description)/meshes/motor_dummy_v2__1__1.stl" scale="0.001 0.001 0.001"/>
    </geometry>
    <material name="silver"/>
  </visual>
  <collision>
    <origin xyz="-0.0574 0.074168 -0.015243" rpy="0 0 0"/>
    <geometry>
      <mesh filename="file://$(find assembly_refined_description)/meshes/motor_dummy_v2__1__1.stl" scale="0.001 0.001 0.001"/>
    </geometry>
  </collision>
</link>

<link name="wheel_v3_1">
  <inertial>
    <origin xyz="-0.019615528936156604 2.3361652080888806e-07 3.689115499767165e-07" rpy="0 0 0"/>
    <mass value="0.2"/>
    <inertia ixx="3e-06" iyy="5e-06" izz="5e-06" ixy="0.0" iyz="0.0" ixz="0.0"/>
  </inertial>
  <visual>
    <origin xyz="0.068 0.07581 -0.015243" rpy="0 0 0"/>
    <geometry>
      <mesh filename="file://$(find assembly_refined_description)/meshes/wheel_v3_1.stl" scale="0.001 0.001 0.001"/>
    </geometry>
    <material name="silver"/>
  </visual>
  <collision>
    <origin xyz="0.068 0.07581 -0.015243" rpy="0 0 0"/>
    <geometry>
      <mesh filename="file://$(find assembly_refined_description)/meshes/wheel_v3_1.stl" scale="0.001 0.001 0.001"/>
    </geometry>
  </collision>
</link>

<link name="wheel_v3__1__1">
  <inertial>
    <origin xyz="0.019615528936156562 -1.2455523157317572e-07 3.68911550582135e-07" rpy="0 0 0"/>
    <mass value="0.2"/>
    <inertia ixx="3e-06" iyy="5e-06" izz="5e-06" ixy="0.0" iyz="-0.0" ixz="-0.0"/>
  </inertial>
  <visual>
    <origin xyz="-0.0684 0.074168 -0.015243" rpy="0 0 0"/>
    <geometry>
      <mesh filename="file://$(find assembly_refined_description)/meshes/wheel_v3__1__1.stl" scale="0.001 0.001 0.001"/>
    </geometry>
    <material name="silver"/>
  </visual>
  <collision>
    <origin xyz="-0.0684 0.074168 -0.015243" rpy="0 0 0"/>
    <geometry>
      <mesh filename="file://$(find assembly_refined_description)/meshes/wheel_v3__1__1.stl" scale="0.001 0.001 0.001"/>
    </geometry>
  </collision>
</link>

<link name="ball_caster_v2_1">
  <inertial>
    <origin xyz="0.006749999999997501 1.5170807555336951e-07 -0.004380227197824322" rpy="0 0 0"/>
    <mass value="0.0035"/>
    <inertia ixx="0.0" iyy="0.0" izz="0.0" ixy="0.0" iyz="-0.0" ixz="0.0"/>
  </inertial>
  <visual>
    <origin xyz="0.00675 -0.044389 -0.010063" rpy="0 0 0"/>
    <geometry>
      <mesh filename="file://$(find assembly_refined_description)/meshes/ball_caster_v2_1.stl" scale="0.001 0.001 0.001"/>
    </geometry>
    <material name="silver"/>
  </visual>
  <collision>
    <origin xyz="0.00675 -0.044389 -0.010063" rpy="0 0 0"/>
    <geometry>
      <mesh filename="file://$(find assembly_refined_description)/meshes/ball_caster_v2_1.stl" scale="0.001 0.001 0.001"/>
    </geometry>
  </collision>
</link>

<link name="camera_v2_1">
  <inertial>
    <origin xyz="2.4348578708810464e-14 -7.871465213209194e-05 0.010799282229860221" rpy="0 0 0"/>
    <mass value="0.1"/>
    <inertia ixx="0.0" iyy="2e-06" izz="2e-06" ixy="-0.0" iyz="0.0" ixz="-0.0"/>
  </inertial>
  <visual>
    <origin xyz="-0.05 -0.075 -0.016063" rpy="0 0 0"/>
    <geometry>
      <mesh filename="file://$(find assembly_refined_description)/meshes/camera_v2_1.stl" scale="0.001 0.001 0.001"/>
    </geometry>
    <material name="silver"/>
  </visual>
  <collision>
    <origin xyz="-0.05 -0.075 -0.016063" rpy="0 0 0"/>
    <geometry>
      <mesh filename="file://$(find assembly_refined_description)/meshes/camera_v2_1.stl" scale="0.001 0.001 0.001"/>
    </geometry>
  </collision>
</link>

<link name="camera_v2__1__1">
  <inertial>
    <origin xyz="2.4355517602714372e-14 -7.871465213209194e-05 0.010799282229860228" rpy="0 0 0"/>
    <mass value="0.1"/>
    <inertia ixx="0.0" iyy="2e-06" izz="2e-06" ixy="-0.0" iyz="0.0" ixz="-0.0"/>
  </inertial>
  <visual>
    <origin xyz="0.05 -0.075 -0.016063" rpy="0 0 0"/>
    <geometry>
      <mesh filename="file://$(find assembly_refined_description)/meshes/camera_v2__1__1.stl" scale="0.001 0.001 0.001"/>
    </geometry>
    <material name="silver"/>
  </visual>
  <collision>
    <origin xyz="0.05 -0.075 -0.016063" rpy="0 0 0"/>
    <geometry>
      <mesh filename="file://$(find assembly_refined_description)/meshes/camera_v2__1__1.stl" scale="0.001 0.001 0.001"/>
    </geometry>
  </collision>
</link>

<link name="camera_v2_1_optical"></link>
<link name="camera_v2__1__1_optical"></link>


<joint name="Rigid 1" type="fixed">
  <origin xyz="0.0479 -0.066989 0.035" rpy="0 0 0"/>
  <parent link="base_link"/>
  <child link="motor_mount_v3_1"/>
</joint>

<joint name="Rigid 2" type="fixed">
  <origin xyz="-0.0475 -0.082989 0.035" rpy="0 0 0"/>
  <parent link="base_link"/>
  <child link="motor_mount_v3__1__1"/>
</joint>

<joint name="Rigid 3" type="fixed">
  <origin xyz="-0.0095 0.007179 -0.019757" rpy="0 0 0"/>
  <parent link="motor_mount_v3__1__1"/>
  <child link="motor_dummy_v2_1"/>
</joint>

<joint name="Rigid 4" type="fixed">
  <origin xyz="0.0095 -0.007179 -0.019757" rpy="0 0 0"/>
  <parent link="motor_mount_v3_1"/>
  <child link="motor_dummy_v2__1__1"/>
</joint>

<joint name="Revolute 5" type="continuous">
  <origin xyz="-0.011 0.0 0.0" rpy="0 0 0"/>
  <parent link="motor_dummy_v2_1"/>
  <child link="wheel_v3_1"/>
  <axis xyz="-1.0 0.0 0.0"/>
</joint>

<joint name="Revolute 6" type="continuous">
  <origin xyz="0.011 0.0 0.0" rpy="0 0 0"/>
  <parent link="motor_dummy_v2__1__1"/>
  <child link="wheel_v3__1__1"/>
  <axis xyz="1.0 -0.0 -0.0"/>
</joint>

<joint name="Rigid 7" type="fixed">
  <origin xyz="-0.00675 0.044389 0.010063" rpy="0 0 0"/>
  <parent link="base_link"/>
  <child link="ball_caster_v2_1"/>
</joint>

<joint name="Rigid 8" type="fixed">
  <origin xyz="0.05 0.075 0.016063" rpy="0 0 0"/>
  <parent link="base_link"/>
  <child link="camera_v2_1"/>
</joint>

<joint name="Rigid 8 Cam" type="fixed">
  <origin xyz="0 0 0" rpy="0 0 1.57"/>
  <parent link="camera_v2_1"/>
  <child link="camera_v2_1_optical"/>
</joint>

<joint name="Rigid 9" type="fixed">
  <origin xyz="-0.05 0.075 0.016063" rpy="0 0 0"/>
  <parent link="base_link"/>
  <child link="camera_v2__1__1"/>
</joint>

<joint name="Rigid 9 Cam" type="fixed">
  <origin xyz="0 0 0" rpy="0 0 1.57"/>
  <parent link="camera_v2__1__1"/>
  <child link="camera_v2__1__1_optical"/>
</joint>

</robot>
